Workbook

Sheet Read me
A1: GenMedia video study — scenario bank and proposed batch
A2: Prepared 2026-09-14. Scenarios tab holds the existing bank (60) and the proposed new scenarios (43) in one sheet — filter on the Group column.
A4: How to review
A5: Only the yellow cells are for you: 'Your decision' (Approve / Change / Drop) and 'Your comments'. Example: Your decision = Change · Your comments = 'Use a basketball clip instead of football'.
A6: Prompts are what will be copied verbatim into the scenario sheet once approved. Adherence checks are what the judge scores.
A8: What the columns mean
A9: Source status — Ready: prepared input is in video/assets/bank with a licence file. Downloaded & verified: original downloaded, SHA-1 checked, eyeballed; input still to cut/crop. Weak candidate / Downloading / Blocked: in progress. NOT FOUND and NO downloadable source: listed with options on the 'Sources not found' tab.
A10: Ground truth (judge only) — a real photo or clip of the target view shown to the judge but never to the models. Needs a small runner change before those scenarios can run.
A11: Est. cost per pair — both arms, one generation each, from the Assumptions tab.
A13: Rules applied to every new scenario
A14: One change per scenario where possible (style OR camera OR timing) so a failure points at one capability.
A15: Licensed, redistributable sources only (CC0, CC BY, CC BY-SA, public domain, official datasets); no famous game IP (recitation and copyright filters would refuse it).
... A17: Face-heavy inputs flagged: Seedance refuses video with identifiable faces, so those get a 1-cell probe first.

Sheet Scenarios
A1: # | B1: Group | C1: Scenario ID | D1: Category | E1: Use-case family | F1: Industry (primary) | G1: Also relevant to | H1: Scenario title | I1: Input asset / clip | J1: Exact transformation / task | K1: Prompt (verbatim — for review) | L1: Expected output (adherence checks) | M1: Capability tested | N1: Why realistic / publishable | O1: Why different from existing scenarios | P1: Source / link | Q1: Licence | R1: Source status | S1: Ground truth (judge only) | T1: Status / last result | U1: In next batch? | V1: Risks & notes | W1: Est. cost per pair (USD) | X1: Your decision | Y1: Your comments
A2: 1 | B2: Available — existing bank | C2: VID-CIN-01 | D2: Text-to-Video | E2: Cinematic / hero shot | F2: Micro-drama & entertainment | G2: Ads, Gaming | H2: Slow dolly-in | I2: none | J2: Camera move accuracy and temporal stability | K2: A slow dolly-in on a woman reading at a wooden table by a window. Soft daylight. The camera moves steadily forward for the full duration. No cuts. | L2: 1) Camera moves forward, not zoom 2) Movement steady, no stutter 3) Single continuous take 4) Subject stays framed | M2: Camera move accuracy and temporal stability | P2: — | Q2: No asset needed | R2: In the bank | S2: — | T2: Pilot run 2026-09-03 (720p) · statistical tie overall; scoped out 2026-09-04 | U2: No — out of scope
A3: 2 | B3: Available — existing bank | C3: VID-CIN-02 | D3: Text-to-Video | E3: Cinematic / hero shot | F3: Micro-drama & entertainment | G3: Ads, Gaming | H3: Golden hour consistency | I3: none | J3: Lighting stability over time | K3: A man walking along a coastal path at golden hour. Warm low sun from behind. The light direction and colour must stay consistent for the whole shot. | L3: 1) Warm low-angle light 2) Light direction constant 3) Colour temperature stable 4) Subject motion continuous | M3: Lighting stability over time | P3: — | Q3: No asset needed | R3: In the bank | S3: — | T3: Pilot run 2026-09-03 (720p) · statistical tie overall; scoped out 2026-09-04 | U3: No — out of scope
A4: 3 | B4: Available — existing bank | C4: VID-CIN-03 | D4: Text-to-Video | E4: Cinematic / hero shot | F4: Micro-drama & entertainment | G4: Ads, Gaming | H4: Handheld documentary | I4: none | J4: Deliberate instability without artefacts | K4: Handheld documentary-style shot following a chef through a busy kitchen. Natural camera shake. Subject stays in frame throughout. | L4: 1) Handheld character present 2) Subject remains in frame 3) Shake reads as camera, not as artefact 4) No frame tearing or warping | M4: Deliberate instability without artefacts | P4: — | Q4: No asset needed | R4: In the bank | S4: — | T4: Pilot run 2026-09-03 (720p) · statistical tie overall; scoped out 2026-09-04 | U4: No — out of scope
A5: 4 | B5: Available — existing bank | C5: VID-CIN-04 | D5: Text-to-Video | E5: Cinematic / hero shot | F5: Micro-drama & entertainment | G5: Ads, Gaming | H5: Rack focus | I5: none | J5: Depth control across the shot | K5: A static shot of a coffee cup in the foreground and a person in the background. Focus starts on the cup and shifts to the person halfway through. | L5: 1) Focus starts on foreground 2) Shifts to background 3) Transition is gradual 4) Camera itself stays static | M5: Depth control across the shot | P5: — | Q5: No asset needed | R5: In the bank | S5: — | T5: Pilot run 2026-09-03 (720p) · statistical tie overall; scoped out 2026-09-04 | U5: No — out of scope
A6: 5 | B6: Available — existing bank | C6: VID-CIN-05 | D6: Text-to-Video | E6: Cinematic / hero shot | F6: Micro-drama & entertainment | G6: Ads, Gaming | H6: Crane reveal | I6: none | J6: Vertical camera move | K6: A rising crane shot starting on a stone path and lifting to reveal a valley of terraced fields. Smooth continuous rise. | L6: 1) Camera rises vertically 2) Reveal occurs 3) Motion smooth throughout 4) No cuts | M6: Vertical camera move | P6: — | Q6: No asset needed | R6: In the bank | S6: — | T6: Never run · text-to-video, out of the edits + image-to-video scope | U6: No — out of scope
A7: 6 | B7: Available — existing bank | C7: VID-CIN-06 | D7: Text-to-Video | E7: Cinematic / hero shot | F7: Micro-drama & entertainment | G7: Ads, Gaming | H7: Low-light interior | I7: none | J7: Noise and detail under difficult exposure | K7: A dimly lit study at night, lit only by a desk lamp. A person turns a page. Warm pooled light, deep shadows, no visible noise. | L7: 1) Low-key lighting with visible falloff 2) Practical lamp is the light source 3) Page turn occurs 4) Shadow detail retained without noise | M7: Noise and detail under difficult exposure | P7: — | Q7: No asset needed | R7: In the bank | S7: — | T7: Never run · text-to-video, out of the edits + image-to-video scope | U7: No — out of scope
A8: 7 | B8: Available — existing bank | C8: VID-CIN-07 | D8: Text-to-Video | E8: Cinematic / hero shot | F8: Micro-drama & entertainment | G8: Ads, Gaming | H8: Weather atmosphere | I8: none | J8: Particle consistency over time | K8: A street at night in steady rain. Rain falls continuously and consistently for the whole shot. Wet reflections on the road. | L8: 1) Rain present throughout 2) Rain direction and density consistent 3) Reflections on wet surfaces 4) No rain popping in or out | M8: Particle consistency over time | P8: — | Q8: No asset needed | R8: In the bank | S8: — | T8: Never run · text-to-video, out of the edits + image-to-video scope | U8: No — out of scope
A9: 8 | B9: Available — existing bank | C9: VID-CIN-08 | D9: Text-to-Video | E9: Cinematic / hero shot | F9: Micro-drama & entertainment | G9: Ads, Gaming | H9: Slow motion physical action | I9: none | J9: Motion plausibility at reduced speed | K9: Slow motion of a ripe tomato dropping onto a wooden board and splitting. Realistic weight and deformation. | L9: 1) Fall reads as slow motion 2) Acceleration consistent with gravity 3) Impact deformation plausible 4) Debris behaves physically | M9: Motion plausibility at reduced speed | P9: — | Q9: No asset needed | R9: In the bank | S9: — | T9: Never run · text-to-video, out of the edits + image-to-video scope | U9: No — out of scope
A10: 9 | B10: Available — existing bank | C10: VID-CIN-09 | D10: Text-to-Video | E10: Cinematic / hero shot | F10: Micro-drama & entertainment | G10: Ads, Gaming | H10: Continuous ten-second take | I10: none | J10: Long-duration coherence | K10: A single continuous ten-second shot following a cyclist along a tree-lined road. No cuts, no jumps, consistent lighting and subject. | L10: 1) Full duration, single take 2) Cyclist identity consistent 3) Lighting consistent 4) No geometry warping | M10: Long-duration coherence | P10: — | Q10: No asset needed | R10: In the bank | S10: — | T10: Never run · text-to-video, out of the edits + image-to-video scope | U10: No — out of scope
A11: 10 | B11: Available — existing bank | C11: VID-CIN-10 | D11: Text-to-Video | E11: Cinematic / hero shot | F11: Micro-drama & entertainment | G11: Ads, Gaming | H11: Match a supplied look reference | I11: Reference still image | J11: Aesthetic transfer to motion | K11: Generate an eight-second shot of a harbour at dawn matching the colour grade, contrast and mood of the supplied still. | L11: 1) Colour grade matches reference 2) Contrast character matches 3) Subject matter as briefed 4) Consistent grade across all frames | M11: Aesthetic transfer to motion | P11: open | Q11: Pexels / Unsplash (free commercial) | R11: In the bank | S11: — | T11: Never run · text-to-video, out of the edits + image-to-video scope | U11: No — out of scope
A12: 11 | B12: Available — existing bank | C12: VID-AD-01 | D12: Image-to-Video | E12: Advertising & product video | F12: Ads | G12: Ecommerce & Retail | H12: Product hero rotation | I12: Product reference image | J12: Label legibility through motion | K12: The supplied product rotates slowly through 360 degrees on a neutral pedestal, studio lit. The label must stay sharp and readable throughout. | L12: 1) Full rotation completed 2) Label legible in every frame where it faces camera 3) Product form unaltered 4) Lighting consistent | M12: Label legibility through motion | P12: open | Q12: Google Scanned Objects (CC BY 4.0) | R12: In the bank | S12: — | T12: Run 2026-09-10 · Omni Flash won (+6.0 pp) | U12: No — already run / retired
A13: 12 | B13: Available — existing bank | C13: VID-AD-02 | D13: Image-to-Video | E13: Advertising & product video | F13: Ads | G13: Ecommerce & Retail | H13: Product in use | I13: Product reference | J13: Hand-object interaction | K13: A pair of hands picks up the supplied product from a counter and opens it. Natural hand movement, correct grip, product unchanged. | L13: 1) Hands grip the product plausibly 2) Product opens as it would in reality 3) Product form and label unaltered 4) Five fingers per hand throughout | M13: Hand-object interaction | P13: open | Q13: Google Scanned Objects (CC BY 4.0) | R13: In the bank | S13: — | T13: Run 2026-09-10 · Omni Flash won (+12.0 pp) | U13: No — already run / retired
... A31: 30 | B31: Available — existing bank | C31: VID-AVA-10 | D31: Avatar / Dialogue | E31: Avatar / presenter / dialogue | F31: Micro-drama & entertainment | G31: Ecommerce & Retail, Ads | H31: Spoken figures with on-screen match | I31: none | J31: Numeric accuracy across modalities | K31: A presenter says exactly: Your total is four thousand two hundred and fifty rupees. The same figure appears on screen as 4,250. | L31: 1) Spoken figure exactly correct 2) On-screen figure reads 4,250 3) Spoken and on-screen figures agree 4) Sync maintained | M31: Numeric accuracy across modalities | P31: — | Q31: No asset needed | R31: In the bank | S31: — | T31: Never run · avatar task not built (needs lip-sync rubric) | U31: No — task not built
A32: 31 | B32: Available — existing bank | C32: VID-I2V-01 | D32: Image-to-Video | E32: Image-to-video / first-last frame | F32: Ads | G32: Ecommerce & Retail, Micro-drama & entertainment, Gaming | H32: Subtle animation of a still | I32: Portrait or scene photograph | J32: Motion without content drift | K32: Animate this photograph with subtle natural motion only — slight hair movement, gentle breathing, small ambient shifts. Nothing in the scene may change or move position. | L32: 1) Motion is subtle and natural 2) No object changes position 3) Identity and scene unchanged 4) First frame matches the supplied image | M32: Motion without content drift | P32: open | Q32: Pexels / Unsplash (free commercial) | R32: In the bank | S32: — | T32: Never run · inputs were generated by gemini-3.1-flash-image | U32: No — overlaps a scenario already run | V32: Every input image was generated by a Google model; using them against a ByteDance arm is a confound. Replace with real photos before any run.
A33: 32 | B33: Available — existing bank | C33: VID-I2V-02 | D33: Image-to-Video | E33: Image-to-video / first-last frame | F33: Ads | G33: Ecommerce & Retail, Micro-drama & entertainment, Gaming | H33: First frame continuation | I33: Reference image | J33: Faithful start-state adherence | K33: Use this image as the exact first frame. Continue it for five seconds with the person turning to look out of the window. | L33: 1) First frame matches the supplied image 2) Turn action completes 3) Identity consistent 4) Scene consistent | M33: Faithful start-state adherence | P33: open | Q33: VBench-I2V image suite | R33: In the bank | S33: — | T33: Never run · inputs were generated by gemini-3.1-flash-image | U33: Optional — only with real (non-generated) inputs | V33: Every input image was generated by a Google model; using them against a ByteDance arm is a confound. Replace with real photos before any run.
A34: 33 | B34: Available — existing bank | C34: VID-I2V-03 | D34: Image-to-Video | E34: Image-to-video / first-last frame | F34: Ads | G34: Ecommerce & Retail, Micro-drama & entertainment, Gaming | H34: First and last frame bridge | I34: Two reference images | J34: Interpolation between two fixed states | K34: Use the first supplied image as the opening frame and the second as the closing frame. Generate a natural five-second transition between them. | L34: 1) Opening frame matches image one 2) Closing frame matches image two 3) Transition is continuous and plausible 4) No mid-clip discontinuity | M34: Interpolation between two fixed states | P34: open | Q34: VBench-I2V image suite | R34: In the bank | S34: — | T34: Never run · inputs were generated by gemini-3.1-flash-image | U34: Optional — only with real (non-generated) inputs | V34: Every input image was generated by a Google model; using them against a ByteDance arm is a confound. Replace with real photos before any run.
A35: 34 | B35: Available — existing bank | C35: VID-I2V-04 | D35: Image-to-Video | E35: Image-to-video / first-last frame | F35: Ads | G35: Ecommerce & Retail, Micro-drama & entertainment, Gaming | H35: Reference character in a new scene | I35: Character reference | J35: Identity transfer into motion | K35: Take the character from the supplied reference and show them walking through a train station. Identity, outfit and build must match the reference. | L35: 1) Character matches reference 2) Walking motion plausible 3) Station setting 4) Identity stable across the clip | M35: Identity transfer into motion | P35: open | Q35: SFHQ synthetic faces | R35: In the bank | S35: — | T35: Never run · inputs were generated by gemini-3.1-flash-image | U35: Optional — only with real (non-generated) inputs | V35: Every input image was generated by a Google model; using them against a ByteDance arm is a confound. Replace with real photos before any run.
A36: 35 | B36: Available — existing bank | C36: VID-I2V-05 | D36: Image-to-Video | E36: Image-to-video / first-last frame | F36: Ads | G36: Ecommerce & Retail, Micro-drama & entertainment, Gaming | H36: Product still to rotation | I36: Product reference | J36: Structure inference from one view | K36: Rotate the supplied product image through 180 degrees to show its other side. Keep the product's form, colour and materials consistent. | L36: 1) Rotation completes 2) Form consistent throughout 3) Colour and material consistent 4) First frame matches the reference | M36: Structure inference from one view | P36: open | Q36: Google Scanned Objects (CC BY 4.0) | R36: In the bank | S36: — | T36: Never run · inputs were generated by gemini-3.1-flash-image | U36: No — overlaps a scenario already run | V36: Every input image was generated by a Google model; using them against a ByteDance arm is a confound. Replace with real photos before any run.
A37: 36 | B37: Available — existing bank | C37: VID-I2V-06 | D37: Image-to-Video | E37: Image-to-video / first-last frame | F37: Ads | G37: Ecommerce & Retail, Micro-drama & entertainment, Gaming | H37: Landscape parallax | I37: Landscape photograph | J37: Depth inference from a flat image | K37: Add a slow lateral camera move to this landscape photograph so that foreground and background separate with natural parallax. | L37: 1) Lateral camera move present 2) Foreground moves faster than background 3) No warping or tearing 4) Scene content unchanged | M37: Depth inference from a flat image | P37: open | Q37: Pexels / Unsplash (free commercial) | R37: In the bank | S37: — | T37: Never run · inputs were generated by gemini-3.1-flash-image | U37: No — overlaps a scenario already run | V37: Every input image was generated by a Google model; using them against a ByteDance arm is a confound. Replace with real photos before any run.
A38: 37 | B38: Available — existing bank | C38: VID-I2V-07 | D38: Image-to-Video | E38: Image-to-video / first-last frame | F38: Ads | G38: Ecommerce & Retail, Micro-drama & entertainment, Gaming | H38: Two references composited | I38: Character reference + environment reference | J38: Multi-input scene assembly | K38: Place the character from the first image into the environment from the second image, and have them walk forward. Both must match their references. | L38: 1) Character matches its reference 2) Environment matches its reference 3) Lighting reconciled between them 4) Walk motion plausible | M38: Multi-input scene assembly | P38: open | Q38: SFHQ synthetic faces | R38: In the bank | S38: — | T38: Never run · inputs were generated by gemini-3.1-flash-image | U38: Optional — only with real (non-generated) inputs | V38: Every input image was generated by a Google model; using them against a ByteDance arm is a confound. Replace with real photos before any run.
A39: 38 | B39: Available — existing bank | C39: VID-I2V-08 | D39: Image-to-Video | E39: Image-to-video / first-last frame | F39: Ads | G39: Ecommerce & Retail, Micro-drama & entertainment, Gaming | H39: Style plate plus motion brief | I39: Style plate image | J39: Aesthetic reference driving generation | K39: Generate a five-second shot of a market street that matches the colour palette and texture of the supplied style plate, with people moving through the frame. | L39: 1) Palette matches the style plate 2) Market street subject 3) People in motion 4) Style consistent across all frames | M39: Aesthetic reference driving generation | P39: open | Q39: Pexels / Unsplash (free commercial) | R39: In the bank | S39: — | T39: Never run · inputs were generated by gemini-3.1-flash-image | U39: Optional — only with real (non-generated) inputs | V39: Every input image was generated by a Google model; using them against a ByteDance arm is a confound. Replace with real photos before any run.
A40: 39 | B40: Available — existing bank | C40: VID-I2V-09 | D40: Image-to-Video | E40: Image-to-video / first-last frame | F40: Ads | G40: Ecommerce & Retail, Micro-drama & entertainment, Gaming | H40: Logo reveal from a still | I40: Logo file | J40: Brand asset animation | K40: Animate the supplied logo revealing itself from a soft blur into sharp focus, settling centred for the final two seconds. | L40: 1) Reveal completes 2) Final logo geometry matches the supplied file 3) Colours accurate 4) Holds still at the end | M40: Brand asset animation | P40: — | Q40: Internal brand kit — build once | R40: In the bank | S40: — | T40: Never run · inputs were generated by gemini-3.1-flash-image | U40: No — overlaps a scenario already run | V40: Every input image was generated by a Google model; using them against a ByteDance arm is a confound. Replace with real photos before any run.
A41: 40 | B41: Available — existing bank | C41: VID-I2V-10 | D41: Image-to-Video | E41: Image-to-video / first-last frame | F41: Ads | G41: Ecommerce & Retail, Micro-drama & entertainment, Gaming | H41: Three stills to a sequence | I41: Three reference stills | J41: Multi-shot assembly from references | K41: Using these three supplied stills in order as key moments, generate a continuous eight-second sequence that moves through all three. | L41: 1) All three states appear, in the supplied order 2) Transitions between them are continuous 3) Subject consistent throughout 4) No content invented beyond the references | M41: Multi-shot assembly from references | P41: open | Q41: VBench-I2V image suite | R41: In the bank | S41: — | T41: Never run · inputs were generated by gemini-3.1-flash-image | U41: Optional — only with real (non-generated) inputs | V41: Every input image was generated by a Google model; using them against a ByteDance arm is a confound. Replace with real photos before any run.
A42: 41 | B42: Available — existing bank | C42: VID-EDIT-01 | D42: Video Editing | E42: Conversational / local video editing | F42: Ads | G42: Micro-drama & entertainment | H42: Recolour one object | I42: Source clip with a red umbrella | J42: Targeted change across all frames | K42: In this clip, change the colour of the red umbrella to yellow. Everything else in the shot must stay exactly as it is. | L42: 1) Umbrella is yellow in every frame 2) Umbrella geometry unchanged 3) Nothing else recoloured 4) Motion unchanged | M42: Targeted change across all frames | P42: open | Q42: Pexels Video (free commercial) | R42: In the bank | S42: — | T42: Run 2026-09-11 · not compared (Seedance face filter) | U42: No — already run / retired
A43: 42 | B43: Available — existing bank | C43: VID-EDIT-02 | D43: Video Editing | E43: Conversational / local video editing | F43: Ads | G43: Micro-drama & entertainment | H43: Remove a background element | I43: Source clip with a static bicycle | J43: Deletion with temporal stability | K43: Remove the parked bicycle from the background of this clip. Reconstruct what is behind it. Do not change the foreground subject or the camera move. | L43: 1) Bicycle absent in all frames 2) Background reconstruction stable, no flicker 3) Foreground subject unchanged 4) Camera move preserved | M43: Deletion with temporal stability | P43: open | Q43: TGVE+ (adds removal / addition) | R43: In the bank | S43: — | T43: Retired 2026-09-09 — brief and clip cannot both be satisfied | U43: No — already run / retired
A44: 43 | B44: Available — existing bank | C44: VID-EDIT-03 | D44: Video Editing | E44: Conversational / local video editing | F44: Ads | G44: Micro-drama & entertainment | H44: Background replacement | I44: Source clip with a person | J44: Matting quality under motion | K44: Replace the background of this clip with a modern office interior. Keep the person, their motion and the lighting on them exactly as they are. | L44: 1) Background replaced throughout 2) Subject edges clean, no fringing 3) Subject motion unchanged 4) Subject lighting unchanged | M44: Matting quality under motion | P44: open | Q44: LOVEU-TGVE-2023 (CC, redistributable) | R44: In the bank | S44: — | T44: Run 2026-09-11 · Omni Flash won (+8.0 pp) | U44: No — already run / retired
A45: 44 | B45: Available — existing bank | C45: VID-EDIT-04 | D45: Video Editing | E45: Conversational / local video editing | F45: Ads | G45: Micro-drama & entertainment | H45: Change time of day | I45: Daytime source clip | J45: Global relight without content change | K45: Change this daytime clip to dusk. Warm low light, longer shadows. Every object, person and movement must stay exactly the same. | L45: 1) Lighting reads as dusk 2) Shadow direction and length changed consistently 3) All objects unchanged in position 4) Motion unchanged | M45: Global relight without content change | P45: open | Q45: LOVEU-TGVE-2023 (CC, redistributable) | R45: In the bank | S45: — | T45: Run 2026-09-11 · not compared (both failed) | U45: No — already run / retired
A46: 45 | B46: Available — existing bank | C46: VID-EDIT-05 | D46: Video Editing | E46: Conversational / local video editing | F46: Ads | G46: Micro-drama & entertainment | H46: Add a physically correct object | I46: Source clip with a table | J46: Insertion with scene interaction | K46: Add a ceramic vase to the empty end of the table in this clip. It must sit correctly on the surface, cast a matching shadow, and stay fixed as the camera moves. | L46: 1) Vase present throughout 2) Sits on the surface, not floating 3) Shadow matches scene lighting 4) Stays locked to the table under camera motion | M46: Insertion with scene interaction | P46: open | Q46: TGVE+ (adds removal / addition) | R46: In the bank | S46: — | T46: Run 2026-09-11 · tie (+0.0 pp) | U46: No — already run / retired
A47: 46 | B47: Available — existing bank | C47: VID-EDIT-06 | D47: Video Editing | E47: Conversational / local video editing | F47: Ads | G47: Micro-drama & entertainment | H47: Extend clip duration | I47: Five-second source clip | J47: Continuity beyond the source | K47: Extend this five-second clip to eight seconds, continuing the existing motion naturally. No repetition, no jump at the join. | L47: 1) Output is eight seconds 2) Original five seconds preserved 3) No visible seam at the join 4) Continued motion is plausible | M47: Continuity beyond the source | P47: open | Q47: LOVEU-TGVE-2023 (CC, redistributable) | R47: In the bank | S47: — | T47: Run 2026-09-11 · not compared (Omni Flash failed) | U47: No — already run / retired
A48: 47 | B48: Available — existing bank | C48: VID-EDIT-07 | D48: Video Editing | E48: Conversational / local video editing | F48: Ads | G48: Micro-drama & entertainment | H48: Change the camera move | I48: Static source clip | J48: Motion re-authoring | K48: Re-render this clip with a slow push-in instead of the existing static framing. Keep the subject, action and lighting identical. | L48: 1) Push-in present 2) Subject and action unchanged 3) Lighting unchanged 4) No warping at frame edges | M48: Motion re-authoring | P48: open | Q48: LOVEU-TGVE-2023 (CC, redistributable) | R48: In the bank | S48: — | T48: Run 2026-09-11 · tie (+0.0 pp) | U48: No — already run / retired
A49: 48 | B49: Available — existing bank | C49: VID-EDIT-08 | D49: Video Editing | E49: Conversational / local video editing | F49: Ads | G49: Micro-drama & entertainment | H49: Three sequential edits | I49: Source clip | J49: Multi-turn drift resistance | K49: Turn 1: make the jacket blue. Turn 2: remove the sign in the background. Turn 3: change the sky to overcast. Each edit must hold and nothing else may drift. | L49: 1) All three edits applied 2) Earlier edits still intact after later turns 3) Nothing outside the three targets changed 4) No cumulative quality loss | M49: Multi-turn drift resistance | P49: open | Q49: LOVEU-TGVE-2023 (CC, redistributable) | R49: In the bank | S49: — | T49: Run 2026-09-11 · not compared (both failed) | U49: No — already run / retired
A50: 49 | B50: Available — existing bank | C50: VID-EDIT-09 | D50: Video Editing | E50: Conversational / local video editing | F50: Ads | G50: Micro-drama & entertainment | H50: Edit on-screen text only | I50: Source clip with on-screen text | J50: Typographic targeted edit | K50: In this clip, change the on-screen text from SALE to OFFER. Match the existing font, size, colour and position. Change nothing else. | L50: 1) Text reads OFFER 2) Font, size, colour match the original 3) Position unchanged 4) Rest of frame unchanged | M50: Typographic targeted edit | P50: open | Q50: Pexels Video (free commercial) | R50: In the bank | S50: — | T50: Run 2026-09-11 · not compared (both failed) | U50: No — already run / retired
A51: 50 | B51: Available — existing bank | C51: VID-EDIT-10 | D51: Video Editing | E51: Conversational / local video editing | F51: Ads | G51: Micro-drama & entertainment | H51: Revert a prior edit | I51: Previously edited clip | J51: Instruction reversal | K51: Following the previous edit, undo the colour change to the jacket and return it to its original colour. Leave all other edits in place. | L51: 1) Jacket returned to original colour 2) Other edits still present 3) No degradation from the round trip 4) Motion unchanged | M51: Instruction reversal | P51: open | Q51: LOVEU-TGVE-2023 (CC, redistributable) | R51: In the bank | S51: — | T51: Not run — no source clip (depends on EDIT-08) | U51: No — already run / retired
A52: 51 | B52: Available — existing bank | C52: VID-PHY-01 | D52: Text-to-Video | E52: Physics & action | F52: Gaming | G52: Micro-drama & entertainment, Ads | H52: Weighted fall | I52: none | J52: Gravity and impact realism | K52: A cast-iron pan falls from a counter onto a tiled floor. It must fall with correct weight, land once, and settle without bouncing unrealistically. | L52: 1) Fall accelerates under gravity 2) Impact is heavy, minimal bounce 3) Pan does not deform 4) Settles in a stable position | M52: Gravity and impact realism | P52: — | Q52: No asset needed | R52: In the bank | S52: — | T52: Pilot run 2026-09-03 (720p) · statistical tie overall; scoped out 2026-09-04 | U52: No — out of scope
A53: 52 | B53: Available — existing bank | C53: VID-PHY-02 | D53: Text-to-Video | E53: Physics & action | F53: Gaming | G53: Micro-drama & entertainment, Ads | H53: Liquid pour | I53: none | J53: Fluid behaviour | K53: Water is poured from a jug into a clear glass until it is about two-thirds full. The stream must be continuous and the level must rise correspondingly. | L53: 1) Continuous stream while pouring 2) Level rises in proportion to what is poured 3) No liquid appearing or vanishing 4) Stops at roughly two-thirds | M53: Fluid behaviour | P53: — | Q53: No asset needed | R53: In the bank | S53: — | T53: Pilot run 2026-09-03 (720p) · statistical tie overall; scoped out 2026-09-04 | U53: No — out of scope
... A61: 60 | B61: Available — existing bank | C61: VID-PHY-10 | D61: Text-to-Video | E61: Physics & action | F61: Gaming | G61: Micro-drama & entertainment, Ads | H61: Wheel rotation | I61: none | J61: Rolling-motion consistency | K61: A bicycle rides past the camera from left to right. Wheel rotation speed must match the forward speed — no sliding, no reversed spin. | L61: 1) Bicycle moves left to right 2) Wheels rotate forward 3) Rotation rate consistent with translation 4) No wheel-slip appearance | M61: Rolling-motion consistency | P61: — | Q61: No asset needed | R61: In the bank | S61: — | T61: Pilot run 2026-09-03 (720p) · statistical tie overall; scoped out 2026-09-04 | U61: No — out of scope
A62: 61 | B62: New — proposed | C62: VID-GAME-01 | D62: Video Editing | E62: Gaming & animation to live action | F62: Media & Entertainment | G62: Gaming, Advertising | H62: Animated characters → live-action actors | I62: 8.0 s continuous shot from Sprite Fright (Blender Studio, 2021), 179–187 s: four stylized characters, one takes a green jar from another; cropped to 16:9, 1080p, audio removed | J62: Re-render the animation as photographed live action while performance, blocking, props, camera, set and light stay locked | K62: Re-render this animated clip as live-action film footage shot on a cinema camera. Each cartoon character becomes a real young adult actor with the same hairstyle, hair colour, clothing, accessories and build. Keep every movement and its timing exactly as it is — including the young man in the cricket sweater taking the green jar and turning it in his hands — along with the camera movement, the forest background and the warm evening light. No cuts. | L62: 1) Photoreal skin, hair, fabric and glass — no cartoon proportions or shading left 2) Characters map one-to-one: tall orange-and-yellow hair + pink top; black ponytail + notepad + hoop earrings; blond in white cable-knit cricket sweater over blue polo + gold watch; red hair, freckles, navy Union Jack T-shirt 3) The red-haired actor holds the jar first, the blond actor takes it and turns it, same timing 4) Positions unchanged, including the ponytail actor passing behind the blond actor's arm 5) Same slow camera push-in 6) Forest background and warm light direction kept 7) No face drift or identity swaps | M62: Cross-domain re-rendering with performance lock; multi-character identity mapping; temporal consistency of newly synthesised faces | N62: Studios turn animatics and cinematics into live-action pitch reels and trailers | O62: Earlier edits changed one local attribute of real footage; none re-rendered a whole shot into another visual domain | P62: https://commons.wikimedia.org/wiki/File:Sprite_Fright_-_Blender_Open_Movie-full_movie.webm | Q62: CC BY 4.0 — Blender Foundation | R62: Ready — downloaded & prepared in assets/bank | S62: — | T62: Not run — proposed 2026-09-14 | U62: Yes — pending your review | V62: Seedance face filter on cartoon faces: 1-cell probe first. 'Young adult' wording avoids photoreal minors. | W62: =IF(D62="Video Editing",Assumptions!$B$2+Assumptions!$B$3,IF(D62="Image-to-Video",Assumptions!$B$4+Assumptions!$B$5,""))
A63: 62 | B63: New — proposed | C63: VID-GAME-02 | D63: Video Editing | E63: Gaming & animation to live action | F63: Gaming | G63: Motorsport, Esports | H63: Kart race gameplay → live-action karting | I63: 6.0 s SuperTuxKart chase-cam clip (2150.5–2156.5 s of a CC BY Grand Prix recording): four karts, one passes on the right, long left-hand sweeper, full game HUD; 1080p30, audio removed | J63: Turn gameplay into a real outdoor go-kart race; karts keep their colours, drivers become helmeted racers, HUD removed; positions, motion, track and chase camera kept | K63: Turn this racing-game clip into real footage of a go-kart race on an outdoor circuit, filmed from a chase camera. Each kart becomes a real racing kart in the same colours, with a helmeted driver in a matching race suit. Remove the entire on-screen game interface. Keep the number of karts, where each one is on the track and how they move — including the pink-and-white kart passing on the right at the start — plus the shape of the track, the red-and-white kerbs, the grandstands and pylons, and the chase-camera movement exactly as in the clip. | L63: 1) Photoreal karts, drivers, tarmac, grass 2) Same karts and colours: dark red/white player kart centre, pink/white kart passing right, cyan kart ahead, white kart far ahead 3) Pink kart passes on the right within the first second 4) HUD fully removed with clean background: timer, 3/3 lap counter, speed dial, minimap, touch buttons, racer column, item icon 5) Same left-hand sweeper, kerbs, grandstands, lattice pylon 6) Same camera path and horizon tilt 7) No fantasy effects added 8) Wheel spin matches speed | M63: Multi-object identity and relative motion through a domain change; overlay removal | N63: 'Game vs reality' marketing, karting and esports promos | O63: First multi-agent motion scenario and first HUD removal; PHY-10 tested wheels on a single text-to-video bicycle | P63: https://commons.wikimedia.org/wiki/File:SuperTuxKart_2.x_GP_with_24%25_handicap_and_road_tracks_(open_source_Mario_Kart-like_Linux_game).webm | Q63: CC BY 3.0 — kimden STK | R63: Ready — downloaded & prepared in assets/bank | S63: — | T63: Not run — proposed 2026-09-14 | U63: Yes — pending your review | V63: Only one pass in the clip; a small item-box puff in the last frames is not scored. | W63: =IF(D63="Video Editing",Assumptions!$B$2+Assumptions!$B$3,IF(D63="Image-to-Video",Assumptions!$B$4+Assumptions!$B$5,""))
A64: 63 | B64: New — proposed | C64: VID-GAME-03 | D64: Video Editing | E64: Gaming & animation to live action | F64: Gaming | G64: Esports marketing, Streaming | H64: Remove the game HUD only, keep the game look | I64: Same 6.0 s SuperTuxKart clip as VID-GAME-02 (isolates removal from realism) | J64: Remove all seven on-screen interface elements and rebuild what is behind them; nothing else changes | K64: Remove every on-screen game interface element from this gameplay clip — the timer, lap counter, speed dial, minimap, touch buttons, racer list and item icon — and fill in the track, sky and scenery behind them. Change nothing else: the game graphics, karts, driving and camera must stay exactly as they are. | L64: 1) All seven HUD elements gone in every frame 2) Filled areas match the moving background — no smears or ghost outlines 3) Game art style unchanged, no realism added 4) Karts, motion and camera identical to the source 5) No flicker where the HUD was | M64: Removal of screen-space overlays over a fast-moving 3D scene (clean-plate reconstruction) | N64: Trailer and highlight editors need HUD-free gameplay | O64: EDIT-02 removed one static object; here seven overlays sit over a moving scene. Pairs with GAME-02 to separate removal from realism | P64: (same as VID-GAME-02) | Q64: CC BY 3.0 — kimden STK | R64: Ready — downloaded & prepared in assets/bank | S64: Source clip itself (unchanged regions must match pixel-for-pixel) | T64: Not run — proposed 2026-09-14 | U64: Yes — pending your review | V64: — | W64: =IF(D64="Video Editing",Assumptions!$B$2+Assumptions!$B$3,IF(D64="Image-to-Video",Assumptions!$B$4+Assumptions!$B$5,""))
...

Sheet Summary
A1: Scenario counts
A3: Category | B3: Available — existing bank | C3: New — proposed | D3: Total
A4: Video Editing | B4: =COUNTIFS(Scenarios!$B$2:$B$104,"Available — existing bank",Scenarios!$D$2:$D$104,A4) | C4: =COUNTIFS(Scenarios!$B$2:$B$104,"New — proposed",Scenarios!$D$2:$D$104,A4) | D4: =B4+C4
A5: Image-to-Video | B5: =COUNTIFS(Scenarios!$B$2:$B$104,"Available — existing bank",Scenarios!$D$2:$D$104,A5) | C5: =COUNTIFS(Scenarios!$B$2:$B$104,"New — proposed",Scenarios!$D$2:$D$104,A5) | D5: =B5+C5
A6: Text-to-Video | B6: =COUNTIFS(Scenarios!$B$2:$B$104,"Available — existing bank",Scenarios!$D$2:$D$104,A6) | C6: =COUNTIFS(Scenarios!$B$2:$B$104,"New — proposed",Scenarios!$D$2:$D$104,A6) | D6: =B6+C6
A7: Avatar / Dialogue | B7: =COUNTIFS(Scenarios!$B$2:$B$104,"Available — existing bank",Scenarios!$D$2:$D$104,A7) | C7: =COUNTIFS(Scenarios!$B$2:$B$104,"New — proposed",Scenarios!$D$2:$D$104,A7) | D7: =B7+C7
A8: Total | B8: =SUM(B4:B7) | C8: =SUM(C4:C7) | D8: =SUM(D4:D7)
A10: New scenarios by source status
A11: Ready — downloaded & prepared in assets/bank | B11: =COUNTIFS(Scenarios!$B$2:$B$104,"New — proposed",Scenarios!$R$2:$R$104,A11)
A12: Downloaded & verified — input to prepare | B12: =COUNTIFS(Scenarios!$B$2:$B$104,"New — proposed",Scenarios!$R$2:$R$104,A12)
A13: Downloading (large file) | B13: =COUNTIFS(Scenarios!$B$2:$B$104,"New — proposed",Scenarios!$R$2:$R$104,A13)
A14: Found — download blocked (Google Drive quota, retry after 24 h) | B14: =COUNTIFS(Scenarios!$B$2:$B$104,"New — proposed",Scenarios!$R$2:$R$104,A14)
A15: Weak candidate — replacement being checked | B15: =COUNTIFS(Scenarios!$B$2:$B$104,"New — proposed",Scenarios!$R$2:$R$104,A15)
A16: NOT FOUND — see 'Sources not found' | B16: =COUNTIFS(Scenarios!$B$2:$B$104,"New — proposed",Scenarios!$R$2:$R$104,A16)
A17: NO downloadable source — needs capture / render / shoot | B17: =COUNTIFS(Scenarios!$B$2:$B$104,"New — proposed",Scenarios!$R$2:$R$104,A17)
A18: Total new | B18: =SUM(B11:B17)
A19: Distinct industries among new scenarios | B19: =SUMPRODUCT((Scenarios!$B$2:$B$104="New — proposed")/COUNTIFS(Scenarios!$B$2:$B$104,Scenarios!$B$2:$B$104,Scenarios!$F$2:$F$104,Scenarios!$F$2:$F$104))
A21: Estimated generation cost if every new scenario runs (USD, both arms) | B21: =SUMIFS(Scenarios!$W$2:$W$104,Scenarios!$B$2:$B$104,"New — proposed")
A22: …of which ready now | B22: =SUMIFS(Scenarios!$W$2:$W$104,Scenarios!$B$2:$B$104,"New — proposed",Scenarios!$R$2:$R$104,"Ready — downloaded & prepared in assets/bank")
A23: Assumptions: see the Assumptions tab (per-call estimates from models.yaml).

Sheet Sources not found
A1: Scenario ID | B1: Scenario title | C1: Why there is no usable source | D1: Options (your call)
A3: A. Not found — no licensed downloadable source matched the brief
A4: VID-POST-03 | B4: Stabilise a handheld walking shot | C4: Every walking video found on Commons is gimbal-stabilised: measured jitter on the best one (Nanjing walking tour) was 0.1 px, so there is no shake to remove. Further probing was rate-limited. | D4: Film a 10 s handheld phone walk in-house (real footage, not generated) · or keep searching once downloads finish · or drop
A5: VID-VFX-02 | B5: Fill empty stands with a crowd | C5: No licensed video of empty stands with a moving camera; results were anthem films and rallies. | D5: Film an empty sports hall or stadium on a phone (real footage) · or drop
A6: VID-VFX-03 | B6: Remove power lines from a drone shot | C6: No licensed drone clip with visible power lines. The best drone clip (Llanarmon-yn-Iâl church, Wales, CC BY 3.0, downloaded) has no wires, but shows cars parked beside the churchyard. | D6: Change the brief to 'remove the parked cars' using that clip · or drop
A7: VID-VFX-04 | B7: Virtual staging of an empty room | C7: No licensed walk-through of an empty room on Commons. | D7: Film a 10 s phone walk-through of an empty room or office in-house · or drop
A8: VID-MOTION-04 | B8: Garment photo → worn on a walking model | C8: Museum collection results were drawings, fabric panels or a child's dress; no adult garment product photo under a clean licence. | D8: Photograph one garment in-house on a plain background · or drop
A10: B. Needs capture, render or shoot (not downloadable by nature)
A11: VID-GAME-04 | B11: Sim-racing replay → cinematic car commercial | C11: No licensed, downloadable sim-racing footage; recording Speed Dreams (GPL / Free Art Licence) ourselves is the clean route. | D11: Record a 6–8 s replay on this Mac (you install the game; ~20 min) · or drop
A12: VID-GAME-05 | B12: Game character render → live-action performer | C12: Needs a character picked in Mixamo with your Adobe login; renders are allowed, raw files are not redistributable. | D12: Pick a character in Mixamo; I render front + back · or drop GAME-05 and CAM-02
A13: VID-CAM-02 | B13: Character turnaround front → back | C13: Same Mixamo renders as VID-GAME-05. | D13: As VID-GAME-05
A14: VID-CAM-05 | B14: Portrait ¾ → profile | C14: A real profile ground truth plus a model release covering AI transformation cannot come from stock photos. | D14: In-house two-photo shoot with a signed release · or drop
A16: C. Found, but the download is temporarily blocked
A17: VID-CAM-06 | B17: Event hall layout orbit | C17: Tanks and Temples Meetingroom.zip (416 MB) is on Google Drive, which now reports 'too many downloads'. | D17: Retry automatically after 24 h — no action needed
A18: VID-CAM-07 | B18: Locomotive close-up → wide pull-back | C18: Train.zip (202 MB), same Drive quota. Frames 00243 → 00137 already chosen from camera poses. | D18: Retry after 24 h
A19: VID-POST-04 | B19: Re-shoot from the other side of the room | C19: Meetingroom.mp4 (4.27 GB), same Drive quota. | D19: Retry after 24 h
A21: Not recommended | C21: Generating any source with an image or video model breaks the study rule that sources are never model-generated, and a Google-generated input favours the Gemini arm (see the VID-I2V-* notes).

Sheet Assumptions
A1: Cost assumption (USD per generation call) | B1: Value | C1: Source
A2: Seedance 2.5 — video edit | B2: 10.5 | C2: video/configs/models.yaml est_usd_per_call(_by_task), 1080p, audio on — measured on the 2026-09-10/11 runs
A3: Omni Flash — video edit | B3: 1.7 | C3: video/configs/models.yaml est_usd_per_call(_by_task), 1080p, audio on — measured on the 2026-09-10/11 runs
A4: Seedance 2.5 — image-to-video | B4: 4.18 | C4: video/configs/models.yaml est_usd_per_call(_by_task), 1080p, audio on — measured on the 2026-09-10/11 runs
A5: Omni Flash — image-to-video | B5: 1.22 | C5: video/configs/models.yaml est_usd_per_call(_by_task), 1080p, audio on — measured on the 2026-09-10/11 runs
A7: Estimates exclude judge cost (a few cents per cell) and retries. Seedance edits bill per second of input+output, so short clips cost less than the estimate.
